Harness Status: OK
Found 2 tests: Fail = 2
Fail Branding  assert_throws: this=true function "() => fn.call(thisValue)" did not throw
Fail Stray argument  assert_equals: expected (number) 0 but got (object) object "[object Object]"
